<?xml version="1.0"?>
<robot name="vista" xmlns:xacro="http://ros.org/wiki/xacro">

  <link name="base_footprint"/>

  <link name="base_link">
    <inertial>
      <origin xyz="-5.59172957473597E-05 -0.000290361698735504 0.0870392390861892" rpy="0 0 0"/>
      <mass value="1.89499142888141"/>
      <inertia
        ixx="0.0158641765170256"
        ixy="3.38082795733725E-06"
        ixz="-1.58125625941425E-07"
        iyy="0.0153351617598045"
        iyz="7.35535085644495E-08"
        izz="0.0308735346658633"/>
    </inertial>
    <visual>
      <origin xyz="0 0 0" rpy="0 0 0"/>
      <geometry>
        <mesh filename="package://my_robot_description/meshes/base_link.STL"/>
      </geometry>
      <material name="bright_green">
        <color rgba="0.0 0.9 0.2 1"/>
      </material>
    </visual>
    <collision>
      <origin xyz="0 0 0" rpy="0 0 0"/>
      <geometry>
        <mesh filename="package://my_robot_description/meshes/base_link.STL"/>
      </geometry>
    </collision>
  </link>

  <joint name="base_joint" type="fixed">
    <parent link="base_footprint"/>
    <child link="base_link"/>
    <origin xyz="0 0 0.041" rpy="0 0 0"/>
  </joint>

  <link name="right_wheel_link">
    <inertial>
      <origin xyz="-6.16658555185889E-06 -0.00271477776277385 2.77555756156289E-17" rpy="0 0 0"/>
      <mass value="2.99939851399686"/>
      <inertia
        ixx="0.00536782101114923"
        ixy="8.34953625300948E-06"
        ixz="9.48808786330002E-19"
        iyy="0.00904360207407503"
        iyz="-8.3192255181922E-19"
        izz="0.00536780204527647"/>
    </inertial>
    <visual>
      <origin xyz="0 0 0" rpy="0 0 0"/>
      <geometry>
        <mesh filename="package://my_robot_description/meshes/right_wheel_link.STL"/>
      </geometry>
      <material name="right_wheel_red">
        <color rgba="0.95 0.05 0.05 1"/>
      </material>
    </visual>
    <collision>
      <origin xyz="0 0 0" rpy="0 0 0"/>
      <geometry>
        <mesh filename="package://my_robot_description/meshes/right_wheel_link.STL"/>
      </geometry>
    </collision>
  </link>

  <joint name="right_wheel_joint" type="continuous">
    <origin xyz="0.00038523 -0.19073 0.038034" rpy="0 0 0"/>
    <parent link="base_link"/>
    <child link="right_wheel_link"/>
    <axis xyz="0.0022715 1 0"/>
    <dynamics damping="0.1" friction="0.1"/>
  </joint>

  <link name="left_wheel_link">
    <inertial>
      <origin xyz="-6.16658555191441E-06 0.00271477776277382 0" rpy="0 0 0"/>
      <mass value="2.99939851399686"/>
      <inertia
        ixx="0.00536782101114923"
        ixy="-8.34953625301294E-06"
        ixz="9.06861238666184E-20"
        iyy="0.00904360207407503"
        iyz="-4.53641750373978E-19"
        izz="0.00536780204527647"/>
    </inertial>
    <visual>
      <origin xyz="0 0 0" rpy="0 0 0"/>
      <geometry>
        <mesh filename="package://my_robot_description/meshes/left_wheel_link.STL"/>
      </geometry>
      <material name="left_wheel_blue">
        <color rgba="0.05 0.25 1.0 1"/>
      </material>
    </visual>
    <collision>
      <origin xyz="0 0 0" rpy="0 0 0"/>
      <geometry>
        <mesh filename="package://my_robot_description/meshes/left_wheel_link.STL"/>
      </geometry>
    </collision>
  </link>

  <joint name="left_wheel_joint" type="continuous">
    <origin xyz="0.00038523 0.19067 0.038034" rpy="0 0 0"/>
    <parent link="base_link"/>
    <child link="left_wheel_link"/>
    <axis xyz="0.0022715 1 0"/>
    <dynamics damping="0.1" friction="0.1"/>
  </joint>

  <link name="lidar_link">
    <inertial>
      <origin xyz="0.00676782080182922 -4.35639378430896E-05 -0.00751652348121995" rpy="0 0 0"/>
      <mass value="1.33540733349919"/>
      <inertia
        ixx="0.000624666379238873"
        ixy="-3.27743253346308E-06"
        ixz="0.000158302703130538"
        iyy="0.000973324044543591"
        iyz="-1.95143396769176E-06"
        izz="0.00110659557257935"/>
    </inertial>
    <visual>
      <origin xyz="0 0 0" rpy="0 0 0"/>
      <geometry>
        <mesh filename="package://my_robot_description/meshes/lidar_link.STL"/>
      </geometry>
      <material name="lidar_yellow">
        <color rgba="1.0 0.85 0.0 1"/>
      </material>
    </visual>
    <collision>
      <origin xyz="0 0 0" rpy="0 0 0"/>
      <geometry>
        <mesh filename="package://my_robot_description/meshes/lidar_link.STL"/>
      </geometry>
    </collision>
  </link>

  <joint name="lidar_joint" type="fixed">
    <origin xyz="-0.010409 0.0011078 0.21995" rpy="0 0 0"/>
    <parent link="base_link"/>
    <child link="lidar_link"/>
  </joint>

</robot>
